Workbook

Sheet LSA data
A1: MCID | B1: CID | C1: Campaign Name | D1: AID | E1: MAID | F1: Advertiser Name | G1: BID | H1: Business | I1: Budget | J1: Start Date | K1: Last 7 Days | L1: Last 30 Days | M1: Service Principal Name | N1: Service Principal Manager | O1: Channel | P1: Google ID | Q1: Notes | R1: MCC | S1: Google Spend
A2: 924-255-5564 | B2: 4377259 | C2: LSA | Brown, Harris and Faulkner | Synthetic | D2: 984335 | E2: 226522 | F2: Mayer LLC | G2: 5673 | H2: Mayer LLC INC | I2: 12453.06 | J2: 46143 | K2: 2746.98 | L2: 65392.16 | M2: Empower Global Relationships | N2: Lynn Houston | O2: National | P2: =VLOOKUP($B2,'Report 2'!$A:$U,15,FALSE) | R2: =VLOOKUP($P2,'MCC data'!$C:$S,3,FALSE) | S2: =VLOOKUP($P2,'MCC data'!$C:$S,13,FALSE)
A3: 699-229-2012 | B3: 1213024 | C3: LSA | Brown, Harris and Faulkner | Synthetic | D3: 984335 | E3: 226522 | F3: Adams, Warner and Gibson | G3: 5673 | H3: Adams, Warner and Gibson INC | I3: 26633.16 | J3: 46099 | K3: 7198.85 | L3: 35341.09 | M3: Empower Global Relationships | N3: Lynn Houston | O3: National | P3: =VLOOKUP($B3,'Report 2'!$A:$U,15,FALSE) | R3: =VLOOKUP($P3,'MCC data'!$C:$S,3,FALSE) | S3: =VLOOKUP($P3,'MCC data'!$C:$S,13,FALSE)
A4: 924-255-5564 | B4: 0279207 | C4: LSA | King, Moore and Anderson | Synthetic | D4: 090391 | E4: 923608 | F4: Simmons-Keller | G4: 5673 | H4: Simmons-Keller INC | I4: 16154.28 | J4: 46143 | K4: 5816.38 | L4: 38168.49 | M4: Empower Global Relationships | N4: Lynn Houston | O4: National | P4: =VLOOKUP($B4,'Report 2'!$A:$U,15,FALSE) | R4: =VLOOKUP($P4,'MCC data'!$C:$S,3,FALSE) | S4: =VLOOKUP($P4,'MCC data'!$C:$S,13,FALSE)
A5: 699-229-2012 | B5: 0014103 | C5: LSA | Adkins, Garner and Ferrell | Synthetic | D5: 201405 | E5: 767346 | F5: Williams, Dudley and Williams | G5: 5673 | H5: Williams, Dudley and Williams INC | I5: 38736.59 | J5: 46080 | K5: 364.78 | L5: 49180.9 | M5: Empower Global Relationships | N5: Lynn Houston | O5: National | P5: =VLOOKUP($B5,'Report 2'!$A:$U,15,FALSE) | R5: =VLOOKUP($P5,'MCC data'!$C:$S,3,FALSE) | S5: =VLOOKUP($P5,'MCC data'!$C:$S,13,FALSE)
A6: 485-905-1145 | B6: 4763391 | C6: LSA | Adkins, Garner and Ferrell | Synthetic | D6: 201405 | E6: 767346 | F6: Morrison-Wood | G6: 5673 | H6: Morrison-Wood INC | I6: 31814.91 | J6: 46127 | K6: 10041.99 | L6: 55246.04 | M6: Empower Global Relationships | N6: Lynn Houston | O6: National | P6: =VLOOKUP($B6,'Report 2'!$A:$U,15,FALSE) | R6: =VLOOKUP($P6,'MCC data'!$C:$S,3,FALSE) | S6: =VLOOKUP($P6,'MCC data'!$C:$S,13,FALSE)
A7: 485-905-1145 | B7: 8016035 | C7: LSA | Neal Inc | Synthetic | D7: 682991 | E7: 797949 | F7: Jones, Taylor and Washington | G7: 5673 | H7: Jones, Taylor and Washington INC | I7: 36176.39 | J7: 46119 | K7: 0 | L7: 20485.58 | M7: Empower Global Relationships | N7: Lynn Houston | O7: National | P7: =VLOOKUP($B7,'Report 2'!$A:$U,15,FALSE) | Q7: Ad is paused | R7: =VLOOKUP($P7,'MCC data'!$C:$S,3,FALSE) | S7: =VLOOKUP($P7,'MCC data'!$C:$S,13,FALSE)
A8: 924-255-5564 | B8: 7403920 | C8: LSA | Neal Inc | Synthetic | D8: 682991 | E8: 797949 | F8: Benson and Sons | G8: 5673 | H8: Benson and Sons INC | I8: 6967.42 | J8: 46143 | K8: 6564.03 | L8: 67884.99 | M8: Empower Global Relationships | N8: Lynn Houston | O8: National | P8: =VLOOKUP($B8,'Report 2'!$A:$U,15,FALSE) | R8: =VLOOKUP($P8,'MCC data'!$C:$S,3,FALSE) | S8: =VLOOKUP($P8,'MCC data'!$C:$S,13,FALSE)
A9: 924-255-5564 | B9: 6741168 | C9: LSA | Solis-Newton | Synthetic | D9: 743566 | E9: 140570 | F9: Hunter-Maddox | G9: 5673 | H9: Hunter-Maddox INC | I9: 33947.36 | J9: 46143 | K9: 13436.92 | L9: 47082.89 | M9: Empower Global Relationships | N9: Lynn Houston | O9: National | P9: =VLOOKUP($B9,'Report 2'!$A:$U,15,FALSE) | R9: =VLOOKUP($P9,'MCC data'!$C:$S,3,FALSE) | S9: =VLOOKUP($P9,'MCC data'!$C:$S,13,FALSE)
A10: 924-255-5564 | B10: 9639972 | C10: LSA | Jensen Ltd | Synthetic | D10: 484845 | E10: 833866 | F10: Martinez Inc | G10: 5673 | H10: Martinez Inc INC | I10: 32335.37 | J10: 46143 | K10: 0 | L10: 105.58 | M10: Empower Global Relationships | N10: Lynn Houston | O10: National | P10: =VLOOKUP($B10,'Report 2'!$A:$U,15,FALSE) | Q10: Ad is paused | R10: =VLOOKUP($P10,'MCC data'!$C:$S,3,FALSE) | S10: =VLOOKUP($P10,'MCC data'!$C:$S,13,FALSE)
A11: 699-229-2012 | B11: 6045981 | C11: LSA | Munoz Inc | Synthetic | D11: 329844 | E11: 714582 | F11: Ramirez LLC | G11: 5673 | H11: Ramirez LLC INC | I11: 48885.03 | J11: 46028 | K11: 8296.66 | L11: 41339.57 | M11: Empower Global Relationships | N11: Lynn Houston | O11: National | P11: =VLOOKUP($B11,'Report 2'!$A:$U,15,FALSE) | R11: =VLOOKUP($P11,'MCC data'!$C:$S,3,FALSE) | S11: =VLOOKUP($P11,'MCC data'!$C:$S,13,FALSE)
A12: 699-229-2012 | B12: 3841770 | C12: LSA | Munoz Inc | Synthetic | D12: 329844 | E12: 714582 | F12: Hubbard-Lee | G12: 5673 | H12: Hubbard-Lee INC | I12: 6388.44 | J12: 46053 | K12: 0 | L12: 61070.73 | M12: Empower Global Relationships | N12: Lynn Houston | O12: National | P12: =VLOOKUP($B12,'Report 2'!$A:$U,15,FALSE) | Q12: - | R12: =VLOOKUP($P12,'MCC data'!$C:$S,3,FALSE) | S12: =VLOOKUP($P12,'MCC data'!$C:$S,13,FALSE)
A13: 699-229-2012 | B13: 1410320 | C13: LSA | Cox, Thornton and Stout | Synthetic | D13: 907675 | E13: 631921 | F13: King-Ellis | G13: 5673 | H13: King-Ellis INC | I13: 44260.23 | J13: 45964 | K13: 0 | L13: 0 | M13: Empower Global Relationships | N13: Lynn Houston | O13: National | P13: =VLOOKUP($B13,'Report 2'!$A:$U,15,FALSE) | Q13: Red(License) Blue(Background check) | R13: =VLOOKUP($P13,'MCC data'!$C:$S,3,FALSE) | S13: =VLOOKUP($P13,'MCC data'!$C:$S,13,FALSE)
A14: 699-229-2012 | B14: 0770993 | C14: LSA | Erickson-Patrick | Synthetic | D14: 266805 | E14: 290959 | F14: Wyatt Group | G14: 5673 | H14: Wyatt Group INC | I14: 20508.05 | J14: 46028 | K14: 0 | L14: 0 | M14: Empower Global Relationships | N14: Lynn Houston | O14: National | P14: =VLOOKUP($B14,'Report 2'!$A:$U,15,FALSE) | Q14: Red(Business Profile) | R14: =VLOOKUP($P14,'MCC data'!$C:$S,3,FALSE) | S14: =VLOOKUP($P14,'MCC data'!$C:$S,13,FALSE)
A15: 699-229-2012 | B15: 3355597 | C15: LSA | Erickson-Patrick | Synthetic | D15: 266805 | E15: 290959 | F15: Keller Group | G15: 5673 | H15: Keller Group INC | I15: 54528.13 | J15: 46064 | K15: 0 | L15: 22183.73 | M15: Empower Global Relationships | N15: Lynn Houston | O15: National | P15: =VLOOKUP($B15,'Report 2'!$A:$U,15,FALSE) | Q15: Ad is paused | R15: =VLOOKUP($P15,'MCC data'!$C:$S,3,FALSE) | S15: =VLOOKUP($P15,'MCC data'!$C:$S,13,FALSE)
A16: 699-229-2012 | B16: 8612737 | C16: LSA | Erickson-Patrick | Synthetic | D16: 266805 | E16: 290959 | F16: Caldwell, Hernandez and Wilkinson | G16: 5673 | H16: Caldwell, Hernandez and Wilkinson INC | I16: 4346.49 | J16: 45911 | K16: 0 | L16: 32017.82 | M16: Empower Global Relationships | N16: Lynn Houston | O16: National | P16: =VLOOKUP($B16,'Report 2'!$A:$U,15,FALSE) | Q16: - | R16: =VLOOKUP($P16,'MCC data'!$C:$S,3,FALSE) | S16: =VLOOKUP($P16,'MCC data'!$C:$S,13,FALSE)
A17: 924-255-5564 | B17: 2958661 | C17: LSA | Ferrell-Wright | Synthetic | D17: 405947 | E17: 570928 | F17: Clarke, Davis and Gilbert | G17: 5673 | H17: Clarke, Davis and Gilbert INC | I17: 10421.23 | J17: 46143 | K17: 6437.41 | L17: 44997.48 | M17: Empower Global Relationships | N17: Lynn Houston | O17: National | P17: =VLOOKUP($B17,'Report 2'!$A:$U,15,FALSE) | R17: =VLOOKUP($P17,'MCC data'!$C:$S,3,FALSE) | S17: =VLOOKUP($P17,'MCC data'!$C:$S,13,FALSE)
A18: 699-229-2012 | B18: 4587014 | C18: LSA | Ferrell-Wright | Synthetic | D18: 405947 | E18: 570928 | F18: Bryant-Park | G18: 5673 | H18: Bryant-Park INC | I18: 18291.99 | J18: 46029 | K18: 0 | L18: 0 | M18: Empower Global Relationships | N18: Lynn Houston | O18: National | P18: =VLOOKUP($B18,'Report 2'!$A:$U,15,FALSE) | Q18: Ad is paused | R18: =VLOOKUP($P18,'MCC data'!$C:$S,3,FALSE) | S18: =VLOOKUP($P18,'MCC data'!$C:$S,13,FALSE)
A19: 924-255-5564 | B19: 4312088 | C19: LSA | Bell, Vargas and West | Synthetic | D19: 072086 | E19: 897556 | F19: Edwards-Jefferson | G19: 5673 | H19: Edwards-Jefferson INC | I19: 48660.34 | J19: 46143 | K19: 4762.03 | L19: 37508.5 | M19: Empower Global Relationships | N19: Lynn Houston | O19: National | P19: =VLOOKUP($B19,'Report 2'!$A:$U,15,FALSE) | R19: =VLOOKUP($P19,'MCC data'!$C:$S,3,FALSE) | S19: =VLOOKUP($P19,'MCC data'!$C:$S,13,FALSE)
A20: 699-229-2012 | B20: 0619718 | C20: LSA | Bell, Vargas and West | Synthetic | D20: 072086 | E20: 897556 | F20: Bishop Inc | G20: 5673 | H20: Bishop Inc INC | I20: 45236.62 | J20: 46099 | K20: 4064.56 | L20: 33096.79 | M20: Empower Global Relationships | N20: Lynn Houston | O20: National | P20: =VLOOKUP($B20,'Report 2'!$A:$U,15,FALSE) | R20: =VLOOKUP($P20,'MCC data'!$C:$S,3,FALSE) | S20: =VLOOKUP($P20,'MCC data'!$C:$S,13,FALSE)
A21: 699-229-2012 | B21: 9118017 | C21: LSA | Warren-Cook | Synthetic | D21: 683035 | E21: 237834 | F21: Jacobson-Alvarez | G21: 5673 | H21: Jacobson-Alvarez INC | I21: 57572.07 | J21: 46036 | K21: 0 | L21: 37334.89 | M21: Empower Global Relationships | N21: Lynn Houston | O21: National | P21: =VLOOKUP($B21,'Report 2'!$A:$U,15,FALSE) | Q21: Ad is paused | R21: =VLOOKUP($P21,'MCC data'!$C:$S,3,FALSE) | S21: =VLOOKUP($P21,'MCC data'!$C:$S,13,FALSE)
A22: 485-905-1145 | B22: 5441663 | C22: LSA | Smith-Hawkins | Synthetic | D22: 339277 | E22: 149790 | F22: Moore Ltd | G22: 0377 | H22: Moore Ltd INC | I22: 25845.05 | J22: 46121 | K22: 11950.03 | L22: 43020.57 | M22: Re-Intermediate Extensible Schemas | N22: Stephen Vargas | O22: DirectLocal | P22: =VLOOKUP($B22,'Report 2'!$A:$U,15,FALSE) | R22: =VLOOKUP($P22,'MCC data'!$C:$S,3,FALSE) | S22: =VLOOKUP($P22,'MCC data'!$C:$S,13,FALSE)
A23: 699-229-2012 | B23: 2717907 | C23: LSA | Valdez, Stout and Martin | Synthetic | D23: 435153 | E23: 415143 | F23: Rivera-Bauer | G23: 5673 | H23: Rivera-Bauer INC | I23: 3693.4 | J23: 45964 | K23: 0 | L23: 0 | M23: Empower Global Relationships | N23: Lynn Houston | O23: National | P23: =VLOOKUP($B23,'Report 2'!$A:$U,15,FALSE) | Q23: Ad is paused | R23: =VLOOKUP($P23,'MCC data'!$C:$S,3,FALSE) | S23: =VLOOKUP($P23,'MCC data'!$C:$S,13,FALSE)
A24: 924-255-5564 | B24: 8243520 | C24: LSA | Rodriguez and Sons | Synthetic | D24: 823403 | E24: 966939 | F24: Powell-Patterson | G24: 5673 | H24: Powell-Patterson INC | I24: 25940.49 | J24: 46143 | K24: 9095.21 | L24: 42346.21 | M24: Empower Global Relationships | N24: Lynn Houston | O24: National | P24: =VLOOKUP($B24,'Report 2'!$A:$U,15,FALSE) | R24: =VLOOKUP($P24,'MCC data'!$C:$S,3,FALSE) | S24: =VLOOKUP($P24,'MCC data'!$C:$S,13,FALSE)
A25: 699-229-2012 | B25: 1880662 | C25: LSA | Jensen Ltd | Synthetic | D25: 484845 | E25: 833866 | F25: Palmer-Boyd | G25: 5673 | H25: Palmer-Boyd INC | I25: 13748.26 | J25: 46028 | K25: 0 | L25: 0 | M25: Empower Global Relationships | N25: Lynn Houston | O25: National | P25: =VLOOKUP($B25,'Report 2'!$A:$U,15,FALSE) | Q25: Red(Insurance & Business Profile) | R25: =VLOOKUP($P25,'MCC data'!$C:$S,3,FALSE) | S25: =VLOOKUP($P25,'MCC data'!$C:$S,13,FALSE)
A26: 924-255-5564 | B26: 8014053 | C26: LSA | Hunt, Ray and Smith | Synthetic | D26: 050570 | E26: 848332 | F26: Shelton, Gamble and Irwin | G26: 5673 | H26: Shelton, Gamble and Irwin INC | I26: 43743.81 | J26: 46143 | K26: 0 | L26: 20484.45 | M26: Empower Global Relationships | N26: Lynn Houston | O26: National | P26: =VLOOKUP($B26,'Report 2'!$A:$U,15,FALSE) | Q26: Yellow(Billing & Background check) | R26: =VLOOKUP($P26,'MCC data'!$C:$S,3,FALSE) | S26: =VLOOKUP($P26,'MCC data'!$C:$S,13,FALSE)
A27: 924-255-5564 | B27: 6619964 | C27: LSA | Patel Inc | Synthetic | D27: 710174 | E27: 527784 | F27: Garcia-Fernandez | G27: 5673 | H27: Garcia-Fernandez INC | I27: 52398.11 | J27: 46143 | K27: 771.52 | L27: 33889.66 | M27: Empower Global Relationships | N27: Lynn Houston | O27: National | P27: =VLOOKUP($B27,'Report 2'!$A:$U,15,FALSE) | R27: =VLOOKUP($P27,'MCC data'!$C:$S,3,FALSE) | S27: =VLOOKUP($P27,'MCC data'!$C:$S,13,FALSE)
A28: 485-905-1145 | B28: 6640961 | C28: LSA | Reyes, Olson and Morgan | Synthetic | D28: 339129 | E28: 558898 | F28: Hernandez, Vang and Reynolds | G28: 8295 | H28: Hernandez, Vang and Reynolds INC | I28: 52743.45 | J28: 46144 | K28: 12230.24 | L28: 16917.32 | M28: E-Enable B2C Experiences | N28: Angela Cole | O28: National | P28: =VLOOKUP($B28,'Report 2'!$A:$U,15,FALSE) | R28: =VLOOKUP($P28,'MCC data'!$C:$S,3,FALSE) | S28: =VLOOKUP($P28,'MCC data'!$C:$S,13,FALSE)
A29: 924-255-5564 | B29: 1750840 | C29: LSA | Paul-Jackson | Synthetic | D29: 168585 | E29: 238338 | F29: Davis, Wright and Stewart | G29: 8295 | H29: Davis, Wright and Stewart INC | I29: 17956.57 | J29: 46142 | K29: 5351.1 | L29: 14548.02 | M29: E-Enable B2C Experiences | N29: Angela Cole | O29: National | P29: =VLOOKUP($B29,'Report 2'!$A:$U,15,FALSE) | R29: =VLOOKUP($P29,'MCC data'!$C:$S,3,FALSE) | S29: =VLOOKUP($P29,'MCC data'!$C:$S,13,FALSE)
A30: 924-255-5564 | B30: 5304145 | C30: LSA | White, Walker and Boyd | Synthetic | D30: 627311 | E30: 597914 | F30: Butler-Mitchell | G30: 5673 | H30: Butler-Mitchell INC | I30: 58538.43 | J30: 46143 | K30: 1959.4 | L30: 24375.49 | M30: Empower Global Relationships | N30: Lynn Houston | O30: National | P30: =VLOOKUP($B30,'Report 2'!$A:$U,15,FALSE) | R30: =VLOOKUP($P30,'MCC data'!$C:$S,3,FALSE) | S30: =VLOOKUP($P30,'MCC data'!$C:$S,13,FALSE)
A31: 924-255-5564 | B31: 9969654 | C31: LSA | Winters, Nelson and Nichols | Synthetic | D31: 656687 | E31: 321065 | F31: Shepard, Harris and Lewis | G31: 2138 | H31: Shepard, Harris and Lewis INC | I31: 45302.53 | J31: 46128 | K31: 6871.28 | L31: 14796.41 | M31: E-Enable B2C Experiences | N31: Angela Cole | O31: National | P31: =VLOOKUP($B31,'Report 2'!$A:$U,15,FALSE) | R31: =VLOOKUP($P31,'MCC data'!$C:$S,3,FALSE) | S31: =VLOOKUP($P31,'MCC data'!$C:$S,13,FALSE)
A32: 485-905-1145 | B32: 0877130 | C32: LSA | Bell-Cook | Synthetic | D32: 166721 | E32: 394590 | F32: Peterson-Gonzalez | G32: 8295 | H32: Peterson-Gonzalez INC | I32: 9627.88 | J32: 46121 | K32: 121.53 | L32: 24248.96 | M32: E-Enable B2C Experiences | N32: Angela Cole | O32: National | P32: =VLOOKUP($B32,'Report 2'!$A:$U,15,FALSE) | R32: =VLOOKUP($P32,'MCC data'!$C:$S,3,FALSE) | S32: =VLOOKUP($P32,'MCC data'!$C:$S,13,FALSE)
A33: 699-229-2012 | B33: 0350002 | C33: LSA | Patterson and Sons | Synthetic | D33: 310234 | E33: 105479 | F33: Foster-Haynes | G33: 8295 | H33: Foster-Haynes INC | I33: 48953.89 | J33: 45619 | K33: 0 | L33: 0 | M33: E-Enable B2C Experiences | N33: Angela Cole | O33: National | P33: =VLOOKUP($B33,'Report 2'!$A:$U,15,FALSE) | Q33: Ad is paused | R33: =VLOOKUP($P33,'MCC data'!$C:$S,3,FALSE) | S33: =VLOOKUP($P33,'MCC data'!$C:$S,13,FALSE)
A34: 924-255-5564 | B34: 6748855 | C34: LSA | Harris and Sons | Synthetic | D34: 268276 | E34: 170580 | F34: Long and Sons | G34: 5673 | H34: Long and Sons INC | I34: 45890.48 | J34: 46143 | K34: 10528.38 | L34: 5565.9 | M34: Empower Global Relationships | N34: Lynn Houston | O34: National | P34: =VLOOKUP($B34,'Report 2'!$A:$U,15,FALSE) | R34: =VLOOKUP($P34,'MCC data'!$C:$S,3,FALSE) | S34: =VLOOKUP($P34,'MCC data'!$C:$S,13,FALSE)
A35: 699-229-2012 | B35: 5805491 | C35: LSA | Hampton-Carrillo | Synthetic | D35: 560065 | E35: 273859 | F35: Richardson-Lee | G35: 5673 | H35: Richardson-Lee INC | I35: 16845.97 | J35: 46038 | K35: 0 | L35: 44571.18 | M35: Empower Global Relationships | N35: Lynn Houston | O35: National | P35: =VLOOKUP($B35,'Report 2'!$A:$U,15,FALSE) | Q35: Red(Insurance & License & Business Profile) | R35: =VLOOKUP($P35,'MCC data'!$C:$S,3,FALSE) | S35: =VLOOKUP($P35,'MCC data'!$C:$S,13,FALSE)
A36: 699-229-2012 | B36: 9679852 | C36: LSA | Hampton-Carrillo | Synthetic | D36: 560065 | E36: 273859 | F36: Murray, Hunter and Stephenson | G36: 5673 | H36: Murray, Hunter and Stephenson INC | I36: 50843.57 | J36: 46028 | K36: 0 | L36: 0 | M36: Empower Global Relationships | N36: Lynn Houston | O36: National | P36: =VLOOKUP($B36,'Report 2'!$A:$U,15,FALSE) | Q36: Red(License) Blue(Business Profile) | R36: =VLOOKUP($P36,'MCC data'!$C:$S,3,FALSE) | S36: =VLOOKUP($P36,'MCC data'!$C:$S,13,FALSE)
A37: 924-255-5564 | B37: 6037777 | C37: LSA | Clark-Merritt | Synthetic | D37: 358165 | E37: 534760 | F37: Wyatt and Sons | G37: 8295 | H37: Wyatt and Sons INC | I37: 30524.1 | J37: 46144 | K37: 10736.95 | L37: 18456.5 | M37: Grow Plug-And-Play Functionalities | N37: Gina Sullivan | O37: National | P37: =VLOOKUP($B37,'Report 2'!$A:$U,15,FALSE) | R37: =VLOOKUP($P37,'MCC data'!$C:$S,3,FALSE) | S37: =VLOOKUP($P37,'MCC data'!$C:$S,13,FALSE)
A38: 485-905-1145 | B38: 9848964 | C38: LSA | Norris-Caldwell | Synthetic | D38: 673726 | E38: 711011 | F38: Daniel-Neal | G38: 8295 | H38: Daniel-Neal INC | I38: 26035.5 | J38: 46116 | K38: 10176.32 | L38: 45544.61 | M38: Revolutionize B2C Platforms | N38: Jason Drake | O38: National | P38: =VLOOKUP($B38,'Report 2'!$A:$U,15,FALSE) | R38: =VLOOKUP($P38,'MCC data'!$C:$S,3,FALSE) | S38: =VLOOKUP($P38,'MCC data'!$C:$S,13,FALSE)
A39: 924-255-5564 | B39: 0551698 | C39: LSA | Bernard-Bell | Synthetic | D39: 372339 | E39: 786774 | F39: Collins and Sons | G39: 9932 | H39: Collins and Sons INC | I39: 50386.73 | J39: 46144 | K39: 8994.38 | L39: 65610.8 | M39: E-Enable B2C Experiences | N39: Angela Cole | O39: National | P39: =VLOOKUP($B39,'Report 2'!$A:$U,15,FALSE) | R39: =VLOOKUP($P39,'MCC data'!$C:$S,3,FALSE) | S39: =VLOOKUP($P39,'MCC data'!$C:$S,13,FALSE)
A40: 699-229-2012 | B40: 4575678 | C40: LSA | Taylor-Miller | Synthetic | D40: 032019 | E40: 339773 | F40: Gray and Sons | G40: 8295 | H40: Gray and Sons INC | I40: 19429.69 | J40: 45276 | K40: 0 | L40: 0 | M40: Grow Plug-And-Play Functionalities | N40: Gina Sullivan | O40: National | P40: =VLOOKUP($B40,'Report 2'!$A:$U,15,FALSE) | Q40: Red(License) | R40: =VLOOKUP($P40,'MCC data'!$C:$S,3,FALSE) | S40: =VLOOKUP($P40,'MCC data'!$C:$S,13,FALSE)
...

Sheet Report 2
A1: CID | B1: Mcid | C1: AID | D1: Maid | E1: BID | F1: Business Name | G1: Budget | H1: Spent | I1: Start | J1: Campaign Created | K1: Paid | L1: Status | M1: AR Status | N1: Channel | O1: Client ID | P1: Offer ID | Q1: Payment Method | R1: Contract Length | S1: Offer Name | T1: Wpc Status | U1: Wpc End Date
A2: 1662148 | B2: 801-048-2685 | C2: 842242 | D2: 042324 | E2: 0746 | F2: Anderson, Summers and Jones | G2: 43633.2 | H2: 0 | I2: 46149 | J2: 46149.484 | K2: 46149.484 | M2: pending | N2: National | O2: 5916500764 | P2: 2303 | Q2: Credit Card | S2: Local Services Ads | T2: running
A3: 7726344 | B3: 801-048-2685 | C3: 349391 | D3: 784017 | E3: 3698 | F3: Thomas and Sons | G3: 83942.15 | H3: 0 | I3: 46150 | J3: 46149.436 | K3: 46149.446 | M3: pending | N3: National | O3: 1492400035 | P3: 2303 | Q3: Credit Card | S3: Local Services Ads | T3: running
A4: 3360119 | B4: 801-048-2685 | C4: 815707 | D4: 465221 | E4: 2816 | F4: Martin, Brown and Frank | G4: 29147.87 | H4: 0 | I4: 46150 | J4: 46149.351 | K4: 46149.352 | M4: pending | N4: DummyG | O4: 2249967510 | P4: 2101 | Q4: Invoice | S4: XMO | T4: running
A5: 3394343 | B5: 801-048-2685 | C5: 396446 | D5: 844265 | E5: 9588 | F5: Hanson, Hall and Case | G5: 24269.33 | H5: 0 | I5: 46149 | J5: 46149.246 | K5: 46149.246 | M5: pending | N5: National | O5: 5370965818 | P5: 1948 | Q5: Credit Card | S5: Local Services Ads | T5: running
A6: 3394343 | B6: 801-048-2685 | C6: 396446 | D6: 844265 | E6: 9588 | F6: Hanson, Hall and Case | G6: 73202.22 | H6: 0 | I6: 46149 | J6: 46149.246 | K6: 46149.246 | M6: pending | N6: National | O6: 5370965818 | P6: 1948 | Q6: Credit Card | S6: Local Services Ads | T6: ended | U6: 45092
A7: 4620908 | B7: 801-048-2685 | C7: 927241 | D7: 172484 | E7: 7521 | F7: Coleman, Brown and Brown | G7: 76437.09 | H7: 0 | I7: 46149 | J7: 46149.218 | K7: 46149.34 | M7: pending | N7: Local | O7: 8598321515 | P7: 2303 | Q7: Invoice | S7: Local Services Ads | T7: running
A8: 7329087 | B8: 801-048-2685 | C8: 927241 | D8: 172484 | E8: 7521 | F8: Hansen, Murphy and Robinson | G8: 35614.74 | H8: 0 | I8: 46149 | J8: 46149.205 | K8: 46149.34 | M8: pending | N8: Local | O8: 1833846387 | P8: 2303 | Q8: Invoice | S8: Local Services Ads | T8: running
A9: 7884442 | B9: 801-048-2685 | C9: 927241 | D9: 172484 | E9: 7521 | F9: Moore, Dawson and Alvarez | G9: 77330.88 | H9: 0 | I9: 46149 | J9: 46149.205 | K9: 46149.34 | M9: pending | N9: Local | O9: 8182903864 | P9: 2303 | Q9: Invoice | S9: Local Services Ads | T9: running
A10: 9787583 | B10: 801-048-2685 | C10: 927241 | D10: 172484 | E10: 7521 | F10: Reyes and Sons | G10: 85429.92 | H10: 0 | I10: 46149 | J10: 46149.205 | K10: 46149.34 | M10: pending | N10: Local | O10: 1843625072 | P10: 2303 | Q10: Invoice | S10: Local Services Ads | T10: running
A11: 5451195 | B11: 801-048-2685 | C11: 927241 | D11: 172484 | E11: 7521 | F11: Hernandez Group | G11: 98126.69 | H11: 0 | I11: 46149 | J11: 46149.205 | K11: 46149.34 | M11: pending | N11: Local | O11: 4203318384 | P11: 2303 | Q11: Invoice | S11: Local Services Ads | T11: running
A12: 6078827 | B12: 801-048-2685 | C12: 927241 | D12: 172484 | E12: 7521 | F12: Morgan, Leach and Jackson | G12: 66602.16 | H12: 0 | I12: 46149 | J12: 46149.204 | K12: 46149.34 | M12: pending | N12: Local | O12: 1776944144 | P12: 2303 | Q12: Invoice | S12: Local Services Ads | T12: running
A13: 0388036 | B13: 801-048-2685 | C13: 927241 | D13: 172484 | E13: 7521 | F13: Serrano-Harrison | G13: 99044.66 | H13: 0 | I13: 46149 | J13: 46149.204 | K13: 46149.34 | M13: pending | N13: Local | O13: 1726373069 | P13: 2303 | Q13: Invoice | S13: Local Services Ads | T13: running
A14: 9369838 | B14: 801-048-2685 | C14: 927241 | D14: 172484 | E14: 7521 | F14: Perez-Perkins | G14: 23813.82 | H14: 0 | I14: 46149 | J14: 46149.204 | K14: 46149.34 | M14: pending | N14: Local | O14: 1642669667 | P14: 2303 | Q14: Invoice | S14: Local Services Ads | T14: running
A15: 3147158 | B15: 801-048-2685 | C15: 893795 | D15: 117515 | E15: 9980 | F15: Bell and Sons | G15: 14805.74 | H15: 0 | I15: 46149 | J15: 46148.679 | K15: 46148.721 | M15: pending | N15: National | O15: 9272488948 | P15: 2303 | Q15: Credit Card | S15: Local Services Ads | T15: running
A16: 0727548 | B16: 801-048-2685 | C16: 395149 | D16: 475343 | E16: 8295 | F16: Perez PLC | G16: 87300.97 | H16: 49437.58 | I16: 46148 | J16: 46148.485 | K16: 46148.485 | M16: pending | N16: National | O16: 8604361768 | P16: 2303 | Q16: Credit Card | S16: Local Services Ads | T16: running
A17: 7426122 | B17: 801-048-2685 | C17: 143001 | D17: 128223 | E17: 8295 | F17: Walton-White | G17: 69148.21 | H17: 46961.26 | I17: 46148 | J17: 46148.485 | K17: 46148.485 | M17: pending | N17: National | O17: 6090633975 | P17: 2303 | Q17: Credit Card | S17: Local Services Ads | T17: running
A18: 6872937 | B18: 801-048-2685 | C18: 202103 | D18: 093295 | E18: 1192 | F18: Riley-Allen | G18: 85649.8 | H18: 0 | I18: 46149 | J18: 46148.485 | K18: 46148.485 | M18: pending | N18: National | O18: 8880158481 | P18: 2303 | Q18: Credit Card | S18: Local Services Ads | T18: running
... A26: 7989742 | B26: 801-048-2685 | C26: 822980 | D26: 444465 | E26: 5673 | F26: Schneider PLC | G26: 25915.1 | H26: 47379.85 | I26: 46147 | J26: 46147.558 | K26: 46147.561 | M26: pending | N26: National | O26: 0690984218 | P26: 1948 | Q26: Invoice | S26: Local Services Ads | T26: running
A27: 7989742 | B27: 801-048-2685 | C27: 822980 | D27: 444465 | E27: 5673 | F27: Schneider PLC | G27: 22282.27 | H27: 7490.39 | I27: 46147 | J27: 46147.558 | K27: 46147.561 | M27: pending | N27: National | O27: 0690984218 | P27: 1948 | Q27: Invoice | S27: Local Services Ads | T27: ended | U27: 45100
A28: 6113154 | B28: 801-048-2685 | C28: 581185 | D28: 006574 | E28: 1192 | F28: Tucker-Wilson | G28: 70760.93 | H28: 40500.86 | I28: 46147 | J28: 46147.483 | K28: 46147.483 | M28: pending | N28: National | O28: 0051367125 | P28: 1948 | Q28: Credit Card | S28: Local Services Ads | T28: running
A29: 6113154 | B29: 801-048-2685 | C29: 581185 | D29: 006574 | E29: 1192 | F29: Tucker-Wilson | G29: 46532.99 | H29: 23362.13 | I29: 46147 | J29: 46147.483 | K29: 46147.483 | M29: pending | N29: National | O29: 0051367125 | P29: 1948 | Q29: Credit Card | S29: Local Services Ads | T29: ended | U29: 45097
A30: 8151652 | B30: 801-048-2685 | C30: 636979 | D30: 118442 | E30: 8295 | F30: Steele PLC | G30: 50392.77 | H30: 59313.19 | I30: 46148 | J30: 46147.482 | K30: 46147.482 | M30: pending | N30: National | O30: 8498634123 | P30: 2303 | Q30: Credit Card | S30: Local Services Ads | T30: running
A31: 8095112 | B31: 801-048-2685 | C31: 921951 | D31: 702707 | E31: 9142 | F31: Clarke PLC | G31: 226.99 | H31: 31239.43 | I31: 46148 | J31: 46147.482 | K31: 46147.572 | M31: pending | N31: Local | O31: 3277829980 | P31: 2303 | Q31: Credit Card | S31: Local Services Ads | T31: running
A32: 8233002 | B32: 801-048-2685 | C32: 024693 | D32: 773341 | E32: 1192 | F32: Hunt PLC | G32: 58025.74 | H32: 18261.89 | I32: 46147 | J32: 46147.482 | K32: 46147.482 | M32: pending | N32: National | O32: 3940476622 | P32: 1948 | Q32: Credit Card | S32: Local Services Ads | T32: running
A33: 8233002 | B33: 801-048-2685 | C33: 024693 | D33: 773341 | E33: 1192 | F33: Hunt PLC | G33: 22064.01 | H33: 49936.36 | I33: 46147 | J33: 46147.482 | K33: 46147.482 | M33: pending | N33: National | O33: 3940476622 | P33: 1948 | Q33: Credit Card | S33: Local Services Ads | T33: ended | U33: 45097
A34: 4792336 | B34: 801-048-2685 | C34: 591675 | D34: 799997 | E34: 1192 | F34: Jones Group | G34: 75000.23 | H34: 56685.9 | I34: 46148 | J34: 46147.482 | K34: 46147.482 | M34: pending | N34: National | O34: 7774057945 | P34: 1948 | Q34: Credit Card | S34: Local Services Ads | T34: ended | U34: 45107
A35: 4792336 | B35: 801-048-2685 | C35: 591675 | D35: 799997 | E35: 1192 | F35: Jones Group | G35: 50974.18 | H35: 3409 | I35: 46148 | J35: 46147.482 | K35: 46147.482 | M35: pending | N35: National | O35: 7774057945 | P35: 1948 | Q35: Credit Card | S35: Local Services Ads | T35: running
A36: 2009716 | B36: 801-048-2685 | C36: 456223 | D36: 517127 | E36: 1192 | F36: Johnson-Mckenzie | G36: 614.04 | H36: 18817.4 | I36: 46147 | J36: 46147.482 | K36: 46147.482 | M36: pending | N36: National | O36: 8318921616 | P36: 2303 | Q36: Credit Card | S36: Local Services Ads | T36: running
A37: 9155643 | B37: 801-048-2685 | C37: 379585 | D37: 681012 | E37: 1192 | F37: Browning, Brown and Pearson | G37: 81725.82 | H37: 46281.57 | I37: 46148 | J37: 46147.482 | K37: 46147.482 | M37: pending | N37: National | O37: 6833184923 | P37: 1948 | Q37: Credit Card | S37: Local Services Ads | T37: running
A38: 9155643 | B38: 801-048-2685 | C38: 379585 | D38: 681012 | E38: 1192 | F38: Browning, Brown and Pearson | G38: 8342.22 | H38: 969.06 | I38: 46148 | J38: 46147.482 | K38: 46147.482 | M38: pending | N38: National | O38: 6833184923 | P38: 1948 | Q38: Credit Card | S38: Local Services Ads | T38: ended | U38: 45098
A39: 6576293 | B39: 801-048-2685 | C39: 356393 | D39: 310835 | E39: 4744 | F39: Hughes, Blair and Gates | G39: 96364.99 | H39: 0 | I39: 46149 | J39: 46147.482 | K39: 46147.482 | M39: pending | N39: National | O39: 2261405045 | P39: 2303 | Q39: Credit Card | S39: Local Services Ads | T39: running
A40: 0838262 | B40: 801-048-2685 | C40: 222228 | D40: 551471 | E40: 6938 | F40: Ramos and Sons | G40: 34723.26 | H40: 28125.18 | I40: 46148 | J40: 46147.482 | K40: 46147.482 | M40: pending | N40: Local | O40: 1057098735 | P40: 2303 | Q40: Credit Card | S40: Local Services Ads | T40: running
A41: 0748354 | B41: 801-048-2685 | C41: 927754 | D41: 826006 | E41: 8295 | F41: Kelley, Smith and Roberson | G41: 92710.46 | H41: 57829.07 | I41: 46148 | J41: 46147.482 | K41: 46147.482 | M41: pending | N41: National | O41: 1270695837 | P41: 1948 | Q41: Credit Card | S41: Local Services Ads | T41: running
A42: 0748354 | B42: 801-048-2685 | C42: 927754 | D42: 826006 | E42: 8295 | F42: Kelley, Smith and Roberson | G42: 9978.87 | H42: 12860.86 | I42: 46148 | J42: 46147.482 | K42: 46147.482 | M42: pending | N42: National | O42: 1270695837 | P42: 1948 | Q42: Credit Card | S42: Local Services Ads | T42: ended | U42: 45092
A43: 5633097 | B43: 801-048-2685 | C43: 885782 | D43: 663601 | E43: 8295 | F43: Lopez-Vasquez | G43: 92632.91 | H43: 31868 | I43: 46147 | J43: 46147.482 | K43: 46147.482 | M43: pending | N43: National | O43: 5550975527 | P43: 2303 | Q43: Credit Card | S43: Local Services Ads | T43: running
A44: 4677946 | B44: 801-048-2685 | C44: 924322 | D44: 623669 | E44: 8295 | F44: Russell, Patel and Cox | G44: 70124.78 | H44: 10598.71 | I44: 46147 | J44: 46147.482 | K44: 46147.482 | M44: pending | N44: National | O44: 1667099462 | P44: 2303 | Q44: Credit Card | S44: Local Services Ads | T44: running
A45: 7688948 | B45: 801-048-2685 | C45: 831255 | D45: 996914 | E45: 9365 | F45: Vazquez PLC | G45: 85316.1 | H45: 0 | I45: 46148 | J45: 46147.482 | K45: 46147.482 | M45: pending | N45: National | O45: 8284447121 | P45: 2303 | Q45: Credit Card | S45: Local Services Ads | T45: running
A46: 8590918 | B46: 801-048-2685 | C46: 049473 | D46: 669031 | E46: 9365 | F46: Santiago Inc | G46: 26482.21 | H46: 0 | I46: 46149 | J46: 46147.481 | K46: 46147.482 | M46: pending | N46: National | O46: 6834399267 | P46: 2303 | Q46: Credit Card | S46: Local Services Ads | T46: running
A47: 1351106 | B47: 801-048-2685 | C47: 466202 | D47: 505141 | E47: 8295 | F47: Barrera Inc | G47: 94905.65 | H47: 27317.83 | I47: 46147 | J47: 46147.481 | K47: 46147.481 | M47: pending | N47: National | O47: 0866982738 | P47: 1948 | Q47: Credit Card | S47: Local Services Ads | T47: ended | U47: 45092
...

Sheet MCC data
A1: Account Status | B1: Account name | C1: Account external customer ID | D1: Optimization score | E1: Direct manager name | F1: Direct manager customer ID | G1: Account type | H1: Clicks | I1: Impr. | J1: CTR | K1: Currency code | L1: Avg. CPC | M1: Converted currency code | N1: Avg. CPC (Converted currency) | O1: Cost | P1: Cost (Converted currency) | Q1: Conversions | R1: Conv. rate | S1: Account labels
A2: Active | B2: Anderson, Summers and Jones | C2: 5916500764 | D2: -- | E2: Google LSA Accounts - US | F2: 801-048-2685 | G2: Google Ads | H2: 12372.49 | I2: 1694847 | J2: 0.1556 | K2: USD | L2: 42.89 | M2: USD | N2: 66.56 | O2: 662864 | P2: 748686.95 | Q2: 4767.4 | R2: 0.0939 | S2: --
A3: Active | B3: Thomas and Sons | C3: 1492400035 | D3: -- | E3: Google LSA Accounts - US | F3: 801-048-2685 | G3: Google Ads | H3: 0 | I3: 0 | J3: -- | K3: USD | L3: -- | M3: USD | N3: -- | O3: 0 | P3: -- | Q3: 0 | R3: 0 | S3: --
A4: Active | B4: Martin, Brown and Frank | C4: 2249967510 | D4: -- | E4: Google LSA Accounts - US | F4: 801-048-2685 | G4: Google Ads | H4: 0 | I4: 0 | J4: -- | K4: USD | L4: -- | M4: USD | N4: -- | O4: 0 | P4: -- | Q4: 0 | R4: 0 | S4: --
A5: Active | B5: Hanson, Hall and Case | C5: 5370965818 | D5: -- | E5: Google LSA Accounts - US | F5: 801-048-2685 | G5: Google Ads | H5: 0 | I5: 0 | J5: -- | K5: USD | L5: -- | M5: USD | N5: -- | O5: 0 | P5: -- | Q5: 0 | R5: 0 | S5: --
A6: Active | B6: Coleman, Brown and Brown | C6: 8598321515 | D6: -- | E6: Google LSA Accounts - US | F6: 801-048-2685 | G6: Google Ads | H6: 81502.8 | I6: 1219369.7 | J6: 0.0996 | K6: USD | L6: 16.68 | M6: USD | N6: 139.56 | O6: 0 | P6: 151240.68 | Q6: 3879.58 | R6: 0.1739 | S6: --
A7: Active | B7: Hansen, Murphy and Robinson | C7: 1833846387 | D7: -- | E7: Google LSA Accounts - US | F7: 801-048-2685 | G7: Google Ads | H7: 0 | I7: 0 | J7: -- | K7: USD | L7: -- | M7: USD | N7: -- | O7: 0 | P7: -- | Q7: 0 | R7: 0 | S7: --
A8: Active | B8: Moore, Dawson and Alvarez | C8: 8182903864 | D8: -- | E8: Google LSA Accounts - US | F8: 801-048-2685 | G8: Google Ads | H8: 47851.51 | I8: 997842.38 | J8: 0.0722 | K8: USD | L8: 3.86 | M8: USD | N8: 106.21 | O8: 452811 | P8: 208125.6 | Q8: 496.68 | R8: 0.1617 | S8: --
A9: Active | B9: Reyes and Sons | C9: 1843625072 | D9: -- | E9: Google LSA Accounts - US | F9: 801-048-2685 | G9: Google Ads | H9: 105055.36 | I9: 830622.13 | J9: 0.0857 | K9: USD | L9: 18.45 | M9: USD | N9: 126.32 | O9: - | P9: 230165.96 | Q9: 1669.06 | R9: 0.1375 | S9: Plumbing Utah
A10: Active | B10: Hernandez Group | C10: 4203318384 | D10: -- | E10: Google LSA Accounts - US | F10: 801-048-2685 | G10: Google Ads | H10: 110353.81 | I10: 353037.02 | J10: 0.073 | K10: USD | L10: 0 | M10: USD | N10: 0 | O10: - | P10: 0 | Q10: 0 | R10: 0 | S10: --
A11: Active | B11: Morgan, Leach and Jackson | C11: 1776944144 | D11: -- | E11: Google LSA Accounts - US | F11: 801-048-2685 | G11: Google Ads | H11: 0 | I11: 0 | J11: -- | K11: USD | L11: -- | M11: USD | N11: -- | O11: 0 | P11: -- | Q11: 0 | R11: 0 | S11: --
A12: Active | B12: Serrano-Harrison | C12: 1726373069 | D12: -- | E12: Google LSA Accounts - US | F12: 801-048-2685 | G12: Google Ads | H12: 29816.7 | I12: 1035248.7 | J12: 0.0599 | K12: USD | L12: 36.98 | M12: USD | N12: 96.9 | O12: 0 | P12: 307008.12 | Q12: 346.82 | R12: 0.0631 | S12: --
A13: Active | B13: Perez-Perkins | C13: 1642669667 | D13: -- | E13: Google LSA Accounts - US | F13: 801-048-2685 | G13: Google Ads | H13: 115033.42 | I13: 7022.96 | J13: 0.0782 | K13: USD | L13: 25.72 | M13: USD | N13: 72.68 | O13: 2 | P13: 199235.73 | Q13: 7282.93 | R13: 0.062 | S13: --
A14: Active | B14: Bell and Sons | C14: 9272488948 | D14: -- | E14: Google LSA Accounts - US | F14: 801-048-2685 | G14: Google Ads | H14: 0 | I14: 0 | J14: -- | K14: USD | L14: -- | M14: USD | N14: -- | O14: 0 | P14: -- | Q14: 0 | R14: 0 | S14: --
A15: Active | B15: Perez PLC | C15: 8604361768 | D15: -- | E15: Google LSA Accounts - US | F15: 801-048-2685 | G15: Google Ads | H15: 114222.92 | I15: 80397.87 | J15: 0.0689 | K15: USD | L15: 13.34 | M15: USD | N15: 145.59 | O15: 669940 | P15: 519744.53 | Q15: 11718.28 | R15: 0.237 | S15: --
A16: Active | B16: Walton-White | C16: 6090633975 | D16: -- | E16: Google LSA Accounts - US | F16: 801-048-2685 | G16: Google Ads | H16: 0 | I16: 0 | J16: -- | K16: USD | L16: -- | M16: USD | N16: -- | O16: 0 | P16: -- | Q16: 0 | R16: 0 | S16: --
A17: Active | B17: Riley-Allen | C17: 8880158481 | D17: -- | E17: Google LSA Accounts - US | F17: 801-048-2685 | G17: Google Ads | H17: 131523.93 | I17: 145239.12 | J17: 0.1894 | K17: USD | L17: 18.67 | M17: USD | N17: 71.06 | O17: 589183 | P17: 377490.59 | Q17: 2073.41 | R17: 0.0262 | S17: --
A18: Active | B18: Gomez-Barker | C18: 2917330873 | D18: -- | E18: Google LSA Accounts - US | F18: 801-048-2685 | G18: Google Ads | H18: 133027.9 | I18: 116662.78 | J18: 0.1098 | K18: USD | L18: 5.92 | M18: USD | N18: 65.86 | O18: 560745 | P18: 667631.88 | Q18: 4471.68 | R18: 0.1583 | S18: Allen HVAC
A19: Active | B19: Sanchez-Walters | C19: 3561265250 | D19: -- | E19: Google LSA Accounts - US | F19: 801-048-2685 | G19: Google Ads | H19: 102873.33 | I19: 378675.83 | J19: 0.0235 | K19: USD | L19: 39.09 | M19: USD | N19: 145.35 | O19: 784833 | P19: 601240.66 | Q19: 7142.47 | R19: 0.1765 | S19: --
A20: Active | B20: Chang, Gardner and Davis | C20: 5531215398 | D20: -- | E20: Google LSA Accounts - US | F20: 801-048-2685 | G20: Google Ads | H20: 0 | I20: 0 | J20: -- | K20: USD | L20: -- | M20: USD | N20: -- | O20: 0 | P20: -- | Q20: 0 | R20: 0 | S20: --
A21: Active | B21: Garrison, Garner and Mitchell | C21: 5753787783 | D21: -- | E21: Google LSA Accounts - US | F21: 801-048-2685 | G21: Google Ads | H21: 0 | I21: 0 | J21: -- | K21: USD | L21: -- | M21: USD | N21: -- | O21: 0 | P21: -- | Q21: 0 | R21: 0 | S21: --
A22: Active | B22: Hernandez, Adams and Roberts | C22: 3053963118 | D22: -- | E22: Google LSA Accounts - US | F22: 801-048-2685 | G22: Google Ads | H22: 0 | I22: 0 | J22: -- | K22: USD | L22: -- | M22: USD | N22: -- | O22: 0 | P22: -- | Q22: 0 | R22: 0 | S22: --
A23: Active | B23: Newton-Flores | C23: 6045301447 | D23: -- | E23: Google LSA Accounts - US | F23: 801-048-2685 | G23: Google Ads | H23: 7493.15 | I23: 334162.35 | J23: 0.1292 | K23: USD | L23: 39.78 | M23: USD | N23: 63.46 | O23: 30534 | P23: 131652.89 | Q23: 8824.15 | R23: 0.1463 | S23: HVAC Utah
A24: Active | B24: Mcdaniel, Carlson and Stein | C24: 9729452134 | D24: -- | E24: Google LSA Accounts - US | F24: 801-048-2685 | G24: Google Ads | H24: 48731.73 | I24: 1687513 | J24: 0.0771 | K24: USD | L24: 7.02 | M24: USD | N24: 79.13 | O24: 196759 | P24: 552838.18 | Q24: 5448.78 | R24: 0.1123 | S24: --
A25: Active | B25: Schneider PLC | C25: 0690984218 | D25: -- | E25: Google LSA Accounts - US | F25: 801-048-2685 | G25: Google Ads | H25: 85228.81 | I25: 1020698.7 | J25: 0.1396 | K25: USD | L25: 29.9 | M25: USD | N25: 125.43 | O25: 320064 | P25: 383857.78 | Q25: 2531.61 | R25: 0.1126 | S25: HVAC Washington
A26: Active | B26: Tucker-Wilson | C26: 0051367125 | D26: -- | E26: Google LSA Accounts - US | F26: 801-048-2685 | G26: Google Ads | H26: 0 | I26: 0 | J26: -- | K26: USD | L26: -- | M26: USD | N26: -- | O26: 0 | P26: -- | Q26: 0 | R26: 0 | S26: --
A27: Active | B27: Steele PLC | C27: 8498634123 | D27: -- | E27: Google LSA Accounts - US | F27: 801-048-2685 | G27: Google Ads | H27: 0 | I27: 1461987.7 | J27: 0 | K27: USD | L27: -- | M27: USD | N27: -- | O27: 0 | P27: 0 | Q27: 0 | R27: 0 | S27: --
A28: Active | B28: Clarke PLC | C28: 3277829980 | D28: -- | E28: Google LSA Accounts - US | F28: 801-048-2685 | G28: Google Ads | H28: 0 | I28: 0 | J28: -- | K28: USD | L28: -- | M28: USD | N28: -- | O28: 0 | P28: -- | Q28: 0 | R28: 0 | S28: --
A29: Active | B29: Hunt PLC | C29: 3940476622 | D29: -- | E29: Google LSA Accounts - US | F29: 801-048-2685 | G29: Google Ads | H29: 0 | I29: 0 | J29: -- | K29: USD | L29: -- | M29: USD | N29: -- | O29: 0 | P29: -- | Q29: 0 | R29: 0 | S29: --
A30: Active | B30: Jones Group | C30: 7774057945 | D30: -- | E30: Google LSA Accounts - US | F30: 801-048-2685 | G30: Google Ads | H30: 0 | I30: 0 | J30: -- | K30: USD | L30: -- | M30: USD | N30: -- | O30: 0 | P30: -- | Q30: 0 | R30: 0 | S30: --
A31: Active | B31: Johnson-Mckenzie | C31: 8318921616 | D31: -- | E31: Google LSA Accounts - US | F31: 801-048-2685 | G31: Google Ads | H31: 102125.79 | I31: 1391408.4 | J31: 0.1393 | K31: USD | L31: 37.81 | M31: USD | N31: 131.01 | O31: 100115 | P31: 825591.48 | Q31: 2574.51 | R31: 0.1715 | S31: --
A32: Active | B32: Browning, Brown and Pearson | C32: 6833184923 | D32: -- | E32: Google LSA Accounts - US | F32: 801-048-2685 | G32: Google Ads | H32: 1745.09 | I32: 829167.54 | J32: 0.09 | K32: USD | L32: 0 | M32: USD | N32: 0 | O32: 0 | P32: 0 | Q32: 0 | R32: 0 | S32: --
A33: Active | B33: Hughes, Blair and Gates | C33: 2261405045 | D33: -- | E33: Google LSA Accounts - US | F33: 801-048-2685 | G33: Google Ads | H33: 306.16 | I33: 297523.26 | J33: 0.112 | K33: USD | L33: 22.2 | M33: USD | N33: 158.35 | O33: 137868 | P33: 822772.45 | Q33: 1675.99 | R33: 0.0056 | S33: --
A34: Active | B34: Ramos and Sons | C34: 1057098735 | D34: -- | E34: Google LSA Accounts - US | F34: 801-048-2685 | G34: Google Ads | H34: 0 | I34: 0 | J34: -- | K34: USD | L34: -- | M34: USD | N34: -- | O34: 0 | P34: -- | Q34: 0 | R34: 0 | S34: --
A35: Active | B35: Kelley, Smith and Roberson | C35: 1270695837 | D35: -- | E35: Google LSA Accounts - US | F35: 801-048-2685 | G35: Google Ads | H35: 0 | I35: 0 | J35: -- | K35: USD | L35: -- | M35: USD | N35: -- | O35: 0 | P35: -- | Q35: 0 | R35: 0 | S35: --
A36: Active | B36: Lopez-Vasquez | C36: 5550975527 | D36: -- | E36: Google LSA Accounts - US | F36: 801-048-2685 | G36: Google Ads | H36: 0 | I36: 0 | J36: -- | K36: USD | L36: -- | M36: USD | N36: -- | O36: 0 | P36: -- | Q36: 0 | R36: 0 | S36: --
A37: Active | B37: Russell, Patel and Cox | C37: 1667099462 | D37: -- | E37: Google LSA Accounts - US | F37: 801-048-2685 | G37: Google Ads | H37: 12385.3 | I37: 1612667.4 | J37: 0.0525 | K37: USD | L37: 21.13 | M37: USD | N37: 59.04 | O37: 635728 | P37: 419024.18 | Q37: 8736.84 | R37: 0.045 | S37: --
A38: Active | B38: Vazquez PLC | C38: 8284447121 | D38: -- | E38: Google LSA Accounts - US | F38: 801-048-2685 | G38: Google Ads | H38: 81532.21 | I38: 862475.37 | J38: 0.0915 | K38: USD | L38: 10.65 | M38: USD | N38: 13.16 | O38: 43002 | P38: 799188.15 | Q38: 4434.82 | R38: 0.1329 | S38: --
A39: Active | B39: Santiago Inc | C39: 6834399267 | D39: -- | E39: Google LSA Accounts - US | F39: 801-048-2685 | G39: Google Ads | H39: 0 | I39: 0 | J39: -- | K39: USD | L39: -- | M39: USD | N39: -- | O39: 0 | P39: -- | Q39: 0 | R39: 0 | S39: --
A40: Active | B40: Barrera Inc | C40: 0866982738 | D40: -- | E40: Google LSA Accounts - US | F40: 801-048-2685 | G40: Google Ads | H40: 0 | I40: 0 | J40: -- | K40: USD | L40: -- | M40: USD | N40: -- | O40: 0 | P40: -- | Q40: 0 | R40: 0 | S40: --
...
